Traceback (most recent call last):
  File "C:\Users\sofmo\miniconda3\Lib\site-packages\jupyter_cache\executors\utils.py", line 58, in single_nb_execution
    executenb(
  File "C:\Users\sofmo\miniconda3\Lib\site-packages\nbclient\client.py", line 1314, in execute
    return NotebookClient(nb=nb, resources=resources, km=km, **kwargs).execute()
           ^^^^^^^^^^^^^^^^^^^^^^^^^^^^^^^^^^^^^^^^^^^^^^^^^^^^^^^^^^^^^^^^^^^^^
  File "C:\Users\sofmo\miniconda3\Lib\site-packages\jupyter_core\utils\__init__.py", line 165, in wrapped
    return loop.run_until_complete(inner)
           ^^^^^^^^^^^^^^^^^^^^^^^^^^^^^^
  File "C:\Users\sofmo\miniconda3\Lib\asyncio\base_events.py", line 687, in run_until_complete
    return future.result()
           ^^^^^^^^^^^^^^^
  File "C:\Users\sofmo\miniconda3\Lib\site-packages\nbclient\client.py", line 709, in async_execute
    await self.async_execute_cell(
  File "C:\Users\sofmo\miniconda3\Lib\site-packages\nbclient\client.py", line 1062, in async_execute_cell
    await self._check_raise_for_error(cell, cell_index, exec_reply)
  File "C:\Users\sofmo\miniconda3\Lib\site-packages\nbclient\client.py", line 918, in _check_raise_for_error
    raise CellExecutionError.from_cell_and_msg(cell, exec_reply_content)
nbclient.exceptions.CellExecutionError: An error occurred while executing the following cell:
------------------
df_bioguide = df_119.copy()
df_bioguide['full_name'] = df_bioguide['first_name'] + ' ' + df_bioguide['last_name']
df_bioguide = df_bioguide[['bioguide_id', 'full_name']]
df_bioguide.head()
------------------


[1;31m---------------------------------------------------------------------------[0m
[1;31mNameError[0m                                 Traceback (most recent call last)
Cell [1;32mIn[3], line 1[0m
[1;32m----> 1[0m df_bioguide [38;5;241m=[39m [43mdf_119[49m[38;5;241m.[39mcopy()
[0;32m      2[0m df_bioguide[[38;5;124m'[39m[38;5;124mfull_name[39m[38;5;124m'[39m] [38;5;241m=[39m df_bioguide[[38;5;124m'[39m[38;5;124mfirst_name[39m[38;5;124m'[39m] [38;5;241m+[39m [38;5;124m'[39m[38;5;124m [39m[38;5;124m'[39m [38;5;241m+[39m df_bioguide[[38;5;124m'[39m[38;5;124mlast_name[39m[38;5;124m'[39m]
[0;32m      3[0m df_bioguide [38;5;241m=[39m df_bioguide[[[38;5;124m'[39m[38;5;124mbioguide_id[39m[38;5;124m'[39m, [38;5;124m'[39m[38;5;124mfull_name[39m[38;5;124m'[39m]]

[1;31mNameError[0m: name 'df_119' is not defined

